<?xml version="1.0" encoding="UTF-8"?>
<!-- Generated by org.testng.reporters.JUnitReportReporter -->
<testsuite hostname="LAPTOP-OLPA0MDN" failures="0" tests="6" name="com.TestCases.TestCaseTC_0002" time="0.005" errors="1" timestamp="2021-08-30T12:08:19 IST" skipped="1">
  <testcase classname="com.TestCases.TestCaseTC_0002" name="test1" time="0.001"/>
  <system-out/>
  <testcase classname="com.TestCases.TestCaseTC_0002" name="test2" time="0.001">
    <error message="
Method TestCaseTC_0002.test2()[pri:0, instance:com.TestCases.TestCaseTC_0002@ffaa6af] should have thrown an exception of type class java.lang.RuntimeException" type="org.testng.TestException">
      <![CDATA[org.testng.TestException: 
Method TestCaseTC_0002.test2()[pri:0, instance:com.TestCases.TestCaseTC_0002@ffaa6af] should have thrown an exception of type class java.lang.RuntimeException
at org.testng.internal.ExpectedExceptionsHolder.noException(ExpectedExceptionsHolder.java:82)
at org.testng.internal.TestInvoker.considerExceptions(TestInvoker.java:747)
at org.testng.internal.TestInvoker.invokeMethod(TestInvoker.java:635)
at org.testng.internal.TestInvoker.invokeTestMethod(TestInvoker.java:174)
at org.testng.internal.MethodRunner.runInSequence(MethodRunner.java:46)
at org.testng.internal.TestInvoker$MethodInvocationAgent.invoke(TestInvoker.java:822)
at org.testng.internal.TestInvoker.invokeTestMethods(TestInvoker.java:147)
at org.testng.internal.TestMethodWorker.invokeTestMethods(TestMethodWorker.java:146)
at org.testng.internal.TestMethodWorker.run(TestMethodWorker.java:128)
at java.base/java.util.ArrayList.forEach(ArrayList.java:1511)
at org.testng.TestRunner.privateRun(TestRunner.java:764)
at org.testng.TestRunner.run(TestRunner.java:585)
at org.testng.SuiteRunner.runTest(SuiteRunner.java:384)
at org.testng.SuiteRunner.runSequentially(SuiteRunner.java:378)
at org.testng.SuiteRunner.privateRun(SuiteRunner.java:337)
at org.testng.SuiteRunner.run(SuiteRunner.java:286)
at org.testng.SuiteRunnerWorker.runSuite(SuiteRunnerWorker.java:53)
at org.testng.SuiteRunnerWorker.run(SuiteRunnerWorker.java:96)
at org.testng.TestNG.runSuitesSequentially(TestNG.java:1218)
at org.testng.TestNG.runSuitesLocally(TestNG.java:1140)
at org.testng.TestNG.runSuites(TestNG.java:1069)
at org.testng.TestNG.run(TestNG.java:1037)
at org.testng.remote.AbstractRemoteTestNG.run(AbstractRemoteTestNG.java:115)
at org.testng.remote.RemoteTestNG.initAndRun(RemoteTestNG.java:251)
at org.testng.remote.RemoteTestNG.main(RemoteTestNG.java:77)
]]>
    </error>
  </testcase> <!-- test2 -->
  <system-out/>
  <testcase classname="com.TestCases.TestCaseTC_0002" name="test4" time="0.000"/>
  <system-out/>
  <testcase classname="com.TestCases.TestCaseTC_0002" name="test3" time="0.001">
    <skipped/>
  </testcase> <!-- test3 -->
  <system-out/>
  <testcase classname="com.TestCases.TestCaseTC_0002" name="test4" time="0.001"/>
  <system-out/>
  <testcase classname="com.TestCases.TestCaseTC_0002" name="test4" time="0.001"/>
  <system-out/>
</testsuite> <!-- com.TestCases.TestCaseTC_0002 -->
